<mujoco>
 	<worldbody>
		<light diffuse=".5 .5 .5" pos="0 0 3" dir="0 0 -1"/>
		<geom type="plane" size="2 2 0.1" rgba=".9 0 0 1"/>
        
		<body name = "main body" pos="0 0 0.5">
 			<joint type="free"/>
 			<geom type="box" size=".4 .4 .03" rgba="0 .9 0 1"/>
            <site name="marker" pos = "0 0 0.05" size="0.05" />
            <site name="robot_center" pos="0 0 0" size="0.01"/>
		
            <body name = "left front wheel" pos="0.45 .45 .01" euler='0 90 0'>
     			<joint name = "left front" type="hinge" axis = "0 0 -1"/>
     			<geom type="cylinder" size=".2 0.02" rgba="0 0 0.9 1" mass="1" friction="0.005 0.005 0.0001"/>
    		</body>
            
            
            <body name = "right front wheel" pos="-0.45 .45 .01" euler='0 90 0'>
     			<joint name = "right front" type="hinge" axis = "0 0 -1"/>
     			<geom type="cylinder" size=".2 0.02" rgba="0 0 0.9 1" mass="1" friction="0.005 0.005 0.0001"/>
    		</body>
            
            
            <body name = "left rear wheel" pos="0.45 -.45 .01" euler='0 90 0'>
     			<joint name = "left rear" type="hinge" axis = "-0 0 -1"/>
     			<geom type="cylinder" size=".06 0.02" rgba="0 0 0.9 1" mass="10" friction="0.005 0.005 0.0001"/>
    		</body>
            
            
            <body name = "right rear wheel" pos="-0.45 -.45 .01" euler='0 90 0'>
     			<joint name = "right rear" type="hinge" axis = "-0 0 -1"/>
     			<geom type="cylinder" size=".06 0.02" rgba="0 0 0.9 1" mass="10" friction="0.005 0.005 0.0001"/>
    		</body>
            
        </body>
        
 	</worldbody>
    <sensor>
		<framepos objtype="site" objname="marker"/>
        <velocimeter name="robot_velocity" site="robot_center"/>
	</sensor>
    <actuator>
 		
        <velocity name="left front motor" joint="left front" kv="10"/>
        <velocity name="right front motor" joint="right front" kv="10"/>
        <motor name="left rear motor" joint="left rear" gear="2"/>
        <motor name="right rear motor" joint="right rear" gear="2"/>
        
 	</actuator>
    
</mujoco>